<sdf version="1.9">
    <model name="x3">
        <pose>0 0 0.053302 0 0 0</pose>
        <link name="X3/base_link">
            <sensor name="navsat" type="navsat">
                <always_on>true</always_on>
                <update_rate>5</update_rate>
                <navsat>
                    <position_sensing>
                        <horizontal>
                            <noise type="gaussian">
                                <mean>0.0</mean>
                                <stddev>0.2</stddev>
                            </noise>
                        </horizontal>
                        <vertical>
                            <noise type="gaussian">
                                <mean>0.0</mean>
                                <stddev>0.2</stddev>
                            </noise>
                        </vertical>
                    </position_sensing>
                </navsat>
            </sensor>
            <sensor name="drone_lidar" type="gpu_lidar">
                <pose>0 0 0.1 0 0 0</pose>
                <topic>lidar</topic>
                <update_rate>10</update_rate>
                <ray>
                    <scan>
                        <horizontal>
                            <samples>640</samples>
                            <resolution>1</resolution>
                            <min_angle>-3.14159</min_angle>
                            <max_angle>3.14159</max_angle>
                        </horizontal>
                        <vertical>
                            <samples>16</samples>
                            <resolution>1</resolution>
                            <min_angle>-0.261799</min_angle>
                            <max_angle>0.261799</max_angle>
                        </vertical>
                    </scan>
                    <range>
                        <min>0.1</min>
                        <max>30.0</max>
                    </range>
                </ray>
            </sensor>
            <sensor name="camera" type="camera">
                <pose>0.1 0 0 0 0 0</pose>
                <topic>camera/image_raw</topic>
                <update_rate>30</update_rate>
                <camera>
                    <horizontal_fov>1.047</horizontal_fov>
                    <image>
                        <width>640</width>
                        <height>480</height>
                    </image>
                </camera>
            </sensor>
            <sensor name="imu_sensor" type="imu">
                <always_on>true</always_on>
                <update_rate>200</update_rate>
                <visualize>false</visualize>

                <imu>
                    <angular_velocity>
                        <x>
                            <noise type="gaussian">
                                <mean>0</mean>
                                <stddev>0.0002</stddev>
                            </noise>
                        </x>
                        <y>
                            <noise type="gaussian">
                                <mean>0</mean>
                                <stddev>0.0002</stddev>
                            </noise>
                        </y>
                        <z>
                            <noise type="gaussian">
                                <mean>0</mean>
                                <stddev>0.0002</stddev>
                            </noise>
                        </z>
                    </angular_velocity>

                    <linear_acceleration>
                        <x>
                            <noise type="gaussian">
                                <mean>0</mean>
                                <stddev>0.01</stddev>
                            </noise>
                        </x>
                        <y>
                            <noise type="gaussian">
                                <mean>0</mean>
                                <stddev>0.01</stddev>
                            </noise>
                        </y>
                        <z>
                            <noise type="gaussian">
                                <mean>0</mean>
                                <stddev>0.01</stddev>
                            </noise>
                        </z>
                    </linear_acceleration>
                </imu>

                <plugin name="gz::sim::systems::Imu"
                    filename="libgz-sim-imu-system.so" />
            </sensor>
            <pose>0 0 0 0 -0 0</pose>
            <inertial>
                <pose>0 0 0 0 -0 0</pose>
                <mass>1.5</mass>
                <inertia>
                    <ixx>0.0347563</ixx>
                    <ixy>0</ixy>
                    <ixz>0</ixz>
                    <iyy>0.07</iyy>
                    <iyz>0</iyz>
                    <izz>0.0977</izz>
                </inertia>
            </inertial>
            <collision name="X3/base_link_inertia_collision">
                <pose>0 0 0 0 -0 0</pose>
                <geometry>
                    <box>
                        <size>0.47 0.47 0.11</size>
                    </box>
                </geometry>
            </collision>
            <visual name="X3/base_link_inertia_visual">
                <pose>0 0 0 0 -0 0</pose>
                <geometry>
                    <mesh>
                        <scale>1 1 1</scale>
                        <uri>
                            https://fuel.gazebosim.org/1.0/openrobotics/models/x3%20uav/6/files/meshes/x3.dae</uri>
                    </mesh>
                </geometry>
            </visual>
        </link>
        <link name="X3/rotor_0">
            <pose>0.13 -0.22 0.023 0 -0 0</pose>
            <inertial>
                <pose>0 0 0 0 -0 0</pose>
                <mass>0.005</mass>
                <inertia>
                    <ixx>9.75e-07</ixx>
                    <ixy>0</ixy>
                    <ixz>0</ixz>
                    <iyy>4.17041e-05</iyy>
                    <iyz>0</iyz>
                    <izz>4.26041e-05</izz>
                </inertia>
            </inertial>
            <collision name="X3/rotor_0_collision">
                <pose>0 0 0 0 -0 0</pose>
                <geometry>
                    <cylinder>
                        <length>0.005</length>
                        <radius>0.1</radius>
                    </cylinder>
                </geometry>
                <surface>
                    <contact>
                        <ode />
                    </contact>
                    <friction>
                        <ode />
                    </friction>
                </surface>
            </collision>
            <visual name="X3/rotor_0_visual">
                <pose>0 0 0 0 -0 0</pose>
                <geometry>
                    <mesh>
                        <scale>0.1 0.1 0.1</scale>
                        <uri>
                            https://fuel.gazebosim.org/1.0/openrobotics/models/x3%20uav/6/files/meshes/propeller_ccw.dae</uri>
                    </mesh>
                </geometry>
                <material>
                    <script>
                        <name>Gazebo/Blue</name>
                        <uri>file://media/materials/scripts/gazebo.material</uri>
                    </script>
                </material>
            </visual>
            <gravity>1</gravity>
            <velocity_decay />
        </link>
        <joint name="X3/rotor_0_joint" type="revolute">
            <child>X3/rotor_0</child>
            <parent>X3/base_link</parent>
            <axis>
                <xyz>0 0 1</xyz>
                <limit>
                    <lower>-1e+16</lower>
                    <upper>1e+16</upper>
                </limit>
                <dynamics>
                    <spring_reference>0</spring_reference>
                    <spring_stiffness>0</spring_stiffness>
                </dynamics>
            </axis>
        </joint>
        <link name="X3/rotor_1">
            <pose>-0.13 0.2 0.023 0 -0 0</pose>
            <inertial>
                <pose>0 0 0 0 -0 0</pose>
                <mass>0.005</mass>
                <inertia>
                    <ixx>9.75e-07</ixx>
                    <ixy>0</ixy>
                    <ixz>0</ixz>
                    <iyy>4.17041e-05</iyy>
                    <iyz>0</iyz>
                    <izz>4.26041e-05</izz>
                </inertia>
            </inertial>
            <collision name="X3/rotor_1_collision">
                <pose>0 0 0 0 -0 0</pose>
                <geometry>
                    <cylinder>
                        <length>0.005</length>
                        <radius>0.1</radius>
                    </cylinder>
                </geometry>
                <surface>
                    <contact>
                        <ode />
                    </contact>
                    <friction>
                        <ode />
                    </friction>
                </surface>
            </collision>
            <visual name="X3/rotor_1_visual">
                <pose>0 0 0 0 -0 0</pose>
                <geometry>
                    <mesh>
                        <scale>0.1 0.1 0.1</scale>
                        <uri>
                            https://fuel.gazebosim.org/1.0/openrobotics/models/x3%20uav/6/files/meshes/propeller_ccw.dae</uri>
                    </mesh>
                </geometry>
                <material>
                    <script>
                        <name>Gazebo/Red</name>
                        <uri>file://media/materials/scripts/gazebo.material</uri>
                    </script>
                </material>
            </visual>
            <gravity>1</gravity>
            <velocity_decay />
        </link>
        <joint name="X3/rotor_1_joint" type="revolute">
            <child>X3/rotor_1</child>
            <parent>X3/base_link</parent>
            <axis>
                <xyz>0 0 1</xyz>
                <limit>
                    <lower>-1e+16</lower>
                    <upper>1e+16</upper>
                </limit>
                <dynamics>
                    <spring_reference>0</spring_reference>
                    <spring_stiffness>0</spring_stiffness>
                </dynamics>
            </axis>
        </joint>
        <link name="X3/rotor_2">
            <pose>0.13 0.22 0.023 0 -0 0</pose>
            <inertial>
                <pose>0 0 0 0 -0 0</pose>
                <mass>0.005</mass>
                <inertia>
                    <ixx>9.75e-07</ixx>
                    <ixy>0</ixy>
                    <ixz>0</ixz>
                    <iyy>4.17041e-05</iyy>
                    <iyz>0</iyz>
                    <izz>4.26041e-05</izz>
                </inertia>
            </inertial>
            <collision name="X3/rotor_2_collision">
                <pose>0 0 0 0 -0 0</pose>
                <geometry>
                    <cylinder>
                        <length>0.005</length>
                        <radius>0.1</radius>
                    </cylinder>
                </geometry>
                <surface>
                    <contact>
                        <ode />
                    </contact>
                    <friction>
                        <ode />
                    </friction>
                </surface>
            </collision>
            <visual name="X3/rotor_2_visual">
                <pose>0 0 0 0 -0 0</pose>
                <geometry>
                    <mesh>
                        <scale>0.1 0.1 0.1</scale>
                        <uri>
                            https://fuel.gazebosim.org/1.0/openrobotics/models/x3%20uav/6/files/meshes/propeller_cw.dae</uri>
                    </mesh>
                </geometry>
                <material>
                    <script>
                        <name>Gazebo/Blue</name>
                        <uri>file://media/materials/scripts/gazebo.material</uri>
                    </script>
                </material>
            </visual>
            <gravity>1</gravity>
            <velocity_decay />
        </link>
        <joint name="X3/rotor_2_joint" type="revolute">
            <child>X3/rotor_2</child>
            <parent>X3/base_link</parent>
            <axis>
                <xyz>0 0 1</xyz>
                <limit>
                    <lower>-1e+16</lower>
                    <upper>1e+16</upper>
                </limit>
                <dynamics>
                    <spring_reference>0</spring_reference>
                    <spring_stiffness>0</spring_stiffness>
                </dynamics>
            </axis>
        </joint>
        <link name="X3/rotor_3">
            <pose>-0.13 -0.2 0.023 0 -0 0</pose>
            <inertial>
                <pose>0 0 0 0 -0 0</pose>
                <mass>0.005</mass>
                <inertia>
                    <ixx>9.75e-07</ixx>
                    <ixy>0</ixy>
                    <ixz>0</ixz>
                    <iyy>4.17041e-05</iyy>
                    <iyz>0</iyz>
                    <izz>4.26041e-05</izz>
                </inertia>
            </inertial>
            <collision name="X3/rotor_3_collision">
                <pose>0 0 0 0 -0 0</pose>
                <geometry>
                    <cylinder>
                        <length>0.005</length>
                        <radius>0.1</radius>
                    </cylinder>
                </geometry>
                <surface>
                    <contact>
                        <ode />
                    </contact>
                    <friction>
                        <ode />
                    </friction>
                </surface>
            </collision>
            <visual name="X3/rotor_3_visual">
                <pose>0 0 0 0 -0 0</pose>
                <geometry>
                    <mesh>
                        <scale>0.1 0.1 0.1</scale>
                        <uri>
                            https://fuel.gazebosim.org/1.0/openrobotics/models/x3%20uav/6/files/meshes/propeller_cw.dae</uri>
                    </mesh>
                </geometry>
                <material>
                    <script>
                        <name>Gazebo/Red</name>
                        <uri>file://media/materials/scripts/gazebo.material</uri>
                    </script>
                </material>
            </visual>
            <gravity>1</gravity>
            <velocity_decay />
        </link>
        <joint name="X3/rotor_3_joint" type="revolute">
            <child>X3/rotor_3</child>
            <parent>X3/base_link</parent>
            <axis>
                <xyz>0 0 1</xyz>
                <limit>
                    <lower>-1e+16</lower>
                    <upper>1e+16</upper>
                </limit>
                <dynamics>
                    <spring_reference>0</spring_reference>
                    <spring_stiffness>0</spring_stiffness>
                </dynamics>
            </axis>
        </joint>
        <plugin filename="gz-sim-multicopter-motor-model-system"
            name="gz::sim::systems::MulticopterMotorModel">
            <robotNamespace>x3</robotNamespace>
            <jointName>X3/rotor_0_joint</jointName>
            <linkName>X3/rotor_0</linkName>
            <turningDirection>ccw</turningDirection>
            <timeConstantUp>0.0125</timeConstantUp>
            <timeConstantDown>0.025</timeConstantDown>
            <maxRotVelocity>1500</maxRotVelocity>
            <motorConstant>8.54858e-06</motorConstant>
            <momentConstant>0.06</momentConstant>
            <commandSubTopic>command/motor_speed</commandSubTopic>
            <motorNumber>0</motorNumber>
        </plugin>

        <plugin filename="gz-sim-multicopter-motor-model-system"
            name="gz::sim::systems::MulticopterMotorModel">
            <robotNamespace>x3</robotNamespace>
            <jointName>X3/rotor_1_joint</jointName>
            <linkName>X3/rotor_1</linkName>
            <turningDirection>ccw</turningDirection>
            <timeConstantUp>0.0125</timeConstantUp>
            <timeConstantDown>0.025</timeConstantDown>
            <maxRotVelocity>1500</maxRotVelocity>
            <motorConstant>8.54858e-06</motorConstant>
            <momentConstant>0.06</momentConstant>
            <commandSubTopic>command/motor_speed</commandSubTopic>
            <motorNumber>1</motorNumber>
        </plugin>

        <plugin filename="gz-sim-multicopter-motor-model-system"
            name="gz::sim::systems::MulticopterMotorModel">
            <robotNamespace>x3</robotNamespace>
            <jointName>X3/rotor_2_joint</jointName>
            <linkName>X3/rotor_2</linkName>
            <turningDirection>cw</turningDirection>
            <timeConstantUp>0.0125</timeConstantUp>
            <timeConstantDown>0.025</timeConstantDown>
            <maxRotVelocity>1500</maxRotVelocity>
            <motorConstant>8.54858e-06</motorConstant>
            <momentConstant>0.06</momentConstant>
            <commandSubTopic>command/motor_speed</commandSubTopic>
            <motorNumber>2</motorNumber>
        </plugin>

        <plugin filename="gz-sim-multicopter-motor-model-system"
            name="gz::sim::systems::MulticopterMotorModel">
            <robotNamespace>x3</robotNamespace>
            <jointName>X3/rotor_3_joint</jointName>
            <linkName>X3/rotor_3</linkName>
            <turningDirection>cw</turningDirection>
            <timeConstantUp>0.0125</timeConstantUp>
            <timeConstantDown>0.025</timeConstantDown>
            <maxRotVelocity>1500</maxRotVelocity>
            <motorConstant>8.54858e-06</motorConstant>
            <momentConstant>0.06</momentConstant>
            <commandSubTopic>command/motor_speed</commandSubTopic>
            <motorNumber>3</motorNumber>
        </plugin>

        <plugin filename="gz-sim-pose-publisher-system"
            name="gz::sim::systems::PosePublisher">
            <publish_link_pose>false</publish_link_pose>
            <publish_nested_model_pose>false</publish_nested_model_pose>
            <publish_model_pose>true</publish_model_pose>
            <update_frequency>50</update_frequency>
        </plugin>
    </model>
</sdf>